<?xml version="1.0" encoding="UTF-8"?>
<!-- Generated by org.testng.reporters.JUnitReportReporter -->
<testsuite ignored="0" hostname="Mahams-MacBook-Air.local" failures="1" tests="2" name="testcasesNG.VerifyLoginFunctionality" time="41.355" errors="0" timestamp="06 May 2021 00:30:56 GMT" skipped="0">
  <testcase classname="testcasesNG.VerifyLoginFunctionality" name="VerifyLoginErrorMsg01" time="19.010"/>
  <testcase classname="testcasesNG.VerifyLoginFunctionality" name="VerifyLoginErrorMsg02" time="22.345">
    <failure message="The following asserts failed:
	expected [https://1992xyz-dev-ed.my.salesforce.com/home/home.jsp?source=lex] but found [https://1992xyz-dev-ed.my.salesforce.com/setup/forcecomHomepage.apexp?setupid=ForceCom]" type="java.lang.AssertionError">
      <![CDATA[java.lang.AssertionError: The following asserts failed:
	expected [https://1992xyz-dev-ed.my.salesforce.com/home/home.jsp?source=lex] but found [https://1992xyz-dev-ed.my.salesforce.com/setup/forcecomHomepage.apexp?setupid=ForceCom]
	at org.testng.asserts.SoftAssert.assertAll(SoftAssert.java:43)
	at testcasesNG.VerifyLoginFunctionality.VerifyLoginErrorMsg02(VerifyLoginFunctionality.java:127)
	at java.base/jdk.internal.reflect.NativeMethodAccessorImpl.invoke0(Native Method)
	at java.base/jdk.internal.reflect.NativeMethodAccessorImpl.invoke(NativeMethodAccessorImpl.java:64)
	at java.base/jdk.internal.reflect.DelegatingMethodAccessorImpl.invoke(DelegatingMethodAccessorImpl.java:43)
	at java.base/java.lang.reflect.Method.invoke(Method.java:564)
	at org.testng.internal.MethodInvocationHelper.invokeMethod(MethodInvocationHelper.java:104)
	at org.testng.internal.Invoker.invokeMethod(Invoker.java:645)
	at org.testng.internal.Invoker.invokeTestMethod(Invoker.java:851)
	at org.testng.internal.Invoker.invokeTestMethods(Invoker.java:1177)
	at org.testng.internal.TestMethodWorker.invokeTestMethods(TestMethodWorker.java:129)
	at org.testng.internal.TestMethodWorker.run(TestMethodWorker.java:112)
	at org.testng.TestRunner.privateRun(TestRunner.java:756)
	at org.testng.TestRunner.run(TestRunner.java:610)
	at org.testng.SuiteRunner.runTest(SuiteRunner.java:387)
	at org.testng.SuiteRunner.runSequentially(SuiteRunner.java:382)
	at org.testng.SuiteRunner.privateRun(SuiteRunner.java:340)
	at org.testng.SuiteRunner.run(SuiteRunner.java:289)
	at org.testng.SuiteRunnerWorker.runSuite(SuiteRunnerWorker.java:52)
	at org.testng.SuiteRunnerWorker.run(SuiteRunnerWorker.java:86)
	at org.testng.TestNG.runSuitesSequentially(TestNG.java:1293)
	at org.testng.TestNG.runSuitesLocally(TestNG.java:1218)
	at org.testng.TestNG.runSuites(TestNG.java:1133)
	at org.testng.TestNG.run(TestNG.java:1104)
	at org.testng.remote.AbstractRemoteTestNG.run(AbstractRemoteTestNG.java:115)
	at org.testng.remote.RemoteTestNG.initAndRun(RemoteTestNG.java:251)
	at org.testng.remote.RemoteTestNG.main(RemoteTestNG.java:77)
]]>
    </failure>
  </testcase> <!-- VerifyLoginErrorMsg02 -->
</testsuite> <!-- testcasesNG.VerifyLoginFunctionality -->
